<?xml version="1.0" encoding="utf-8"?>
<!-- =================================================================================== -->
<!-- |    This document was autogenerated by xacro from kr10r900_2.xacro               | -->
<!-- |    EDITING THIS FILE BY HAND IS NOT RECOMMENDED                                 | -->
<!-- =================================================================================== -->
<robot name="kuka_kr10r900_2">
  <link name="base_link">
    <collision>
      <origin rpy="0 0 0" xyz="-0.076 0 .115"/>
      <geometry>
         <box size=".356 .203 .229" />
      </geometry>
    </collision>
  </link>
  <link name="link_1">
    <collision>
      <origin rpy="0 0 0" xyz="0 0 -.05"/>
      <geometry>
         <box size="0.216 .203 .254" />
      </geometry>
    </collision>
  </link>
  <link name="link_2">
    <collision>
      <origin rpy="0 0 0" xyz="0.216 0 0"/>
      <geometry>
         <box size="0.610 .254 .165" />
      </geometry>
    </collision>
  </link>
  <link name="link_3">
    <collision>
      <origin rpy="0 0 0" xyz="0.134 0 0"/>
      <geometry>
         <box size="0.279 .127 .127" />
      </geometry>
    </collision>
  </link>
  <link name="link_4">
    <collision>
      <origin rpy="0 0 0" xyz=".35 0 0"/>
      <geometry>
         <box size="0.254 .152 .102" />
      </geometry>
    </collision>
  </link>
  <link name="link_5">
    <collision>
      <origin rpy="0 0 0" xyz="0 0 0"/>
      <geometry>
         <box size="0.127 .102 .102" />
      </geometry>
    </collision>
  </link>
  <link name="link_6">
  </link>
  <joint name="joint_a1" type="revolute">
    <origin rpy="0 0 0" xyz="0 0 0.400"/>
    <parent link="base_link"/>
    <child link="link_1"/>
    <axis xyz="0 0 -1"/>
    <limit effort="0" lower="-2.96705972839" upper="2.96705972839" velocity="5.23598775598"/>
  </joint>
  <joint name="joint_a2" type="revolute">
    <origin rpy="0 0 0" xyz="0.025 0 0"/>
    <parent link="link_1"/>
    <child link="link_2"/>
    <axis xyz="0 1 0"/>
    <limit effort="0" lower="-3.31612557879" upper="0.785398163397" velocity="3.92699081699"/>
  </joint>
  <joint name="joint_a3" type="revolute">
    <origin rpy="0 0 0" xyz="0.455 0 0"/>
    <parent link="link_2"/>
    <child link="link_3"/>
    <axis xyz="0 1 0"/>
    <limit effort="0" lower="-2.09439510239" upper="2.72271363311" velocity="5.75958653158"/>
  </joint>
  <joint name="joint_a4" type="revolute">
    <origin rpy="0 0 0" xyz="0 0 0.025"/>
    <parent link="link_3"/>
    <child link="link_4"/>
    <axis xyz="-1 0 0"/>
    <limit effort="0" lower="-3.22885911619" upper="3.22885911619" velocity="6.28318530718"/>
  </joint>
  <joint name="joint_a5" type="revolute">
    <origin rpy="0 0 0" xyz="0.420 0 0"/>
    <parent link="link_4"/>
    <child link="link_5"/>
    <axis xyz="0 1 0"/>
    <limit effort="0" lower="-2.09439510239" upper="2.09439510239" velocity="6.28318530718"/>
  </joint>
  <joint name="joint_a6" type="revolute">
    <origin rpy="0 0 0" xyz="0.090 0 0"/>
    <parent link="link_5"/>
    <child link="link_6"/>
    <axis xyz="-1 0 0"/>
    <limit effort="0" lower="-6.10865238198" upper="6.10865238198" velocity="7.55727566114"/>
  </joint>
  <!-- ROS-Industrial 'base' frame: base_link to KUKA $ROBROOT coordinate system transform -->
  <link name="base"/>
  <joint name="base_link-base" type="fixed">
    <origin rpy="0 0 0" xyz="0 0 0"/>
    <parent link="base_link"/>
    <child link="base"/>
  </joint>
  <!-- ROS-Industrial 'flange' frame: attachment point for EEF models -->
  <link name="flange"/>
  <joint name="joint_6-flange" type="fixed">
    <origin rpy="0 0 0" xyz="0 0 0"/>
    <parent link="link_6"/>
    <child link="flange"/>
  </joint>
  <!-- ROS-Industrial 'tool0' frame: all-zeros tool frame -->
  <!-- This frame corresponds to the $FLANGE coordinate system in KUKA KRC controllers. -->
  <link name="tool0"/>
  <joint name="flange-tool0" type="fixed">
    <parent link="flange"/>
    <child link="tool0"/>
    <origin rpy="0 1.57079632679 0" xyz="0 0 0"/>
  </joint>
</robot>
